<sdf version='1.7'>
  <model name='ur16e_robot'>
    <joint name="fixed_to_ground" type="fixed">
      <parent>world</parent>
      <child>base_link</child>
    </joint>
    <link name='base_link'>
      <inertial>
        <pose>0 0 0 0 -0 0</pose>
        <mass>4</mass>
        <inertia>
          <ixx>0.00610633</ixx>
          <ixy>0</ixy>
          <ixz>0</ixz>
          <iyy>0.00610633</iyy>
          <iyz>0</iyz>
          <izz>0.01125</izz>
        </inertia>
      </inertial>
      <collision name='base_link_inertia_collision'>
        <pose>0 0 0 0 0 -0</pose>
        <geometry>
          <mesh>
            <scale>1 1 1</scale>
            <uri>model://ur16e/meshes/collision/base.stl</uri>
          </mesh>
        </geometry>
      </collision>
      <visual name='base_link_inertia_visual'>
        <pose>0 0 0 0 0 -0</pose>
        <geometry>
          <mesh>
            <scale>1 1 1</scale>
            <uri>model://ur16e/meshes/visual/base.dae</uri>
          </mesh>
        </geometry>
      </visual>
    </link>
    <joint name='shoulder_pan_joint' type='revolute'>
      <pose relative_to='base_link'>0 0 0.1807 0 -0 3.14159</pose>
      <parent>base_link</parent>
      <child>shoulder_link</child>
      <axis>
        <xyz>0 0 1</xyz>
        <limit>
          <lower>-6.28319</lower>
          <upper>6.28319</upper>
          <effort>330</effort>
          <velocity>2.0944</velocity>
        </limit>
        <dynamics>
          <damping>0</damping>
          <friction>0</friction>
          <spring_reference>0</spring_reference>
          <spring_stiffness>0</spring_stiffness>
        </dynamics>
      </axis>
    </joint>
    <link name='shoulder_link'>
      <pose relative_to='shoulder_pan_joint'>0 0 0 0 -0 0</pose>
      <inertial>
        <pose>0 -0.03 -0.016 1.5708 -0 0</pose>
        <mass>7.369</mass>
        <inertia>
          <ixx>0.03351</ixx>
          <ixy>2e-05</ixy>
          <ixz>-1e-05</ixz>
          <iyy>0.03374</iyy>
          <iyz>0.00374</iyz>
          <izz>0.021</izz>
        </inertia>
      </inertial>
      <collision name='shoulder_link_collision'>
        <pose>0 0 0 0 -0 3.14159</pose>
        <geometry>
          <mesh>
            <scale>1 1 1</scale>
            <uri>model://ur16e/meshes/collision/shoulder.stl</uri>
          </mesh>
        </geometry>
      </collision>
      <visual name='shoulder_link_visual'>
        <pose>0 0 0 0 -0 3.14159</pose>
        <geometry>
          <mesh>
            <scale>1 1 1</scale>
            <uri>model://ur16e/meshes/visual/shoulder.dae</uri>
          </mesh>
        </geometry>
      </visual>
    </link>
    <joint name='shoulder_lift_joint' type='revolute'>
      <pose relative_to='shoulder_link'>0 0 0 1.5708 -0 0</pose>
      <parent>shoulder_link</parent>
      <child>upper_arm_link</child>
      <axis>
        <xyz>0 0 1</xyz>
        <limit>
          <lower>-6.28319</lower>
          <upper>6.28319</upper>
          <effort>330</effort>
          <velocity>2.0944</velocity>
        </limit>
        <dynamics>
          <damping>0</damping>
          <friction>0</friction>
          <spring_reference>0</spring_reference>
          <spring_stiffness>0</spring_stiffness>
        </dynamics>
      </axis>
    </joint>
    <link name='upper_arm_link'>
      <pose relative_to='shoulder_lift_joint'>0 0 0 0 -0 0</pose>
      <inertial>
        <pose>-0.1764 0 0.16 0 -0 0</pose>
        <mass>10.45</mass>
        <inertia>
          <ixx>0.02796</ixx>
          <ixy>-0.0001</ixy>
          <ixz>-0.0072</ixz>
          <iyy>0.47558</iyy>
          <iyz>3e-05</iyz>
          <izz>0.47635</izz>
        </inertia>
      </inertial>
      <collision name='upper_arm_link_collision'>
        <pose>0 0 0.176 1.5708 0 -1.5708</pose>
        <geometry>
          <mesh>
            <scale>1 1 1</scale>
            <uri>model://ur16e//meshes/collision/upperarm.stl</uri> 
          </mesh>
        </geometry>
      </collision>
      <visual name='upper_arm_link_visual'>
        <pose>0 0 0.176 1.5708 0 -1.5708</pose>
        <geometry>
          <mesh>
            <scale>1 1 1</scale>
            <uri>model://ur16e//meshes/visual/upperarm.dae</uri>
          </mesh>
        </geometry>
      </visual>
    </link>
    <joint name='elbow_joint' type='revolute'>
      <pose relative_to='upper_arm_link'>-0.4784 0 0 0 -0 0</pose>
      <parent>upper_arm_link</parent>
      <child>forearm_link</child>
      <axis>
        <xyz>0 0 1</xyz>
        <limit>
          <lower>-3.14159</lower>
          <upper>3.14159</upper>
          <effort>150</effort>
          <velocity>3.14159</velocity>
        </limit>
        <dynamics>
          <damping>0</damping>
          <friction>0</friction>
          <spring_reference>0</spring_reference>
          <spring_stiffness>0</spring_stiffness>
        </dynamics>
      </axis>
    </joint>
    <link name='forearm_link'>
      <pose relative_to='elbow_joint'>0 0 0 0 -0 0</pose>
      <inertial>
        <pose>-0.166 0 0.065 0 -0 0</pose>
        <mass>4.321</mass>
        <inertia>
          <ixx>0.01091</ixx>
          <ixy>6e-05</ixy>
          <ixz>0.01012</ixz>
          <iyy>0.1206</iyy>
          <iyz>1e-05</iyz>
          <izz>0.11714</izz>
        </inertia>
      </inertial>
      <collision name='forearm_link_collision'>
        <pose>0 0 0.04 1.5708 0 -1.5708</pose>
        <geometry>
          <mesh>
            <scale>1 1 1</scale>
            <uri>model://ur16e/meshes/collision/forearm.stl</uri>
          </mesh>
        </geometry>
      </collision>
      <visual name='forearm_link_visual'>
        <pose>0 0 0.04 1.5708 0 -1.5708</pose>
        <geometry>
          <mesh>
            <scale>1 1 1</scale>
            <uri>model://ur16e//meshes/visual/forearm.dae</uri>
          </mesh>
        </geometry>
      </visual>
    </link>
    <joint name='wrist_1_joint' type='revolute'>
      <pose relative_to='forearm_link'>-0.36 0 0.17415 0 -0 0</pose>
      <parent>forearm_link</parent>
      <child>wrist_1_link</child>
      <axis>
        <xyz>0 0 1</xyz>
        <limit>
          <lower>-6.28319</lower>
          <upper>6.28319</upper>
          <effort>54</effort>
          <velocity>3.14159</velocity>
        </limit>
        <dynamics>
          <damping>0</damping>
          <friction>0</friction>
          <spring_reference>0</spring_reference>
          <spring_stiffness>0</spring_stiffness>
        </dynamics>
      </axis>
    </joint>
    <link name='wrist_1_link'>
      <pose relative_to='wrist_1_joint'>0 0 0 0 -0 0</pose>
      <inertial>
        <pose>0 -0.011 -0.009 1.5708 -0 0</pose>
        <mass>2.18</mass>
        <inertia>
          <ixx>0.00609</ixx>
          <ixy>-1e-05</ixy>
          <ixz>0</ixz>
          <iyy>0.00245</iyy>
          <iyz>0.00083</iyz>
          <izz>0.00579</izz>
        </inertia>
      </inertial>
      <collision name='wrist_1_link_collision'>
        <pose>0 0 -0.135 1.5708 -0 0</pose>
        <geometry>
          <mesh>
            <scale>1 1 1</scale>
            <uri>model://ur16e/meshes/collision/wrist1.stl</uri>
          </mesh>
        </geometry>
      </collision>
      <visual name='wrist_1_link_visual'>
        <pose>0 0 -0.135 1.5708 -0 0</pose>
        <geometry>
          <mesh>
            <scale>1 1 1</scale>
            <uri>model://ur16e/meshes/visual/wrist1.dae</uri>
          </mesh>
        </geometry>
      </visual>
    </link>
    <joint name='wrist_2_joint' type='revolute'>
      <pose relative_to='wrist_1_link'>0 -0.11985 -0 1.5708 -0 0</pose>
      <parent>wrist_1_link</parent>
      <child>wrist_2_link</child>
      <axis>
        <xyz>0 0 1</xyz>
        <limit>
          <lower>-6.28319</lower>
          <upper>6.28319</upper>
          <effort>54</effort>
          <velocity>3.14159</velocity>
        </limit>
        <dynamics>
          <damping>0</damping>
          <friction>0</friction>
          <spring_reference>0</spring_reference>
          <spring_stiffness>0</spring_stiffness>
        </dynamics>
      </axis>
    </joint>
    <link name='wrist_2_link'>
      <pose relative_to='wrist_2_joint'>0 0 0 0 -0 0</pose>
      <inertial>
        <pose>0 0.012 -0.018 -1.5708 0 0</pose>
        <mass>2.033</mass>
        <inertia>
          <ixx>0.00389</ixx>
          <ixy>-1e-05</ixy>
          <ixz>0</ixz>
          <iyy>0.00219</iyy>
          <iyz>-0.00045</iyz>
          <izz>0.00363</izz>
        </inertia>
      </inertial>
      <collision name='wrist_2_link_collision'>
        <pose>0 0 -0.12 0 -0 0</pose>
        <geometry>
          <mesh>
            <scale>1 1 1</scale>
            <uri>model://ur16e/meshes/collision/wrist2.stl</uri>
          </mesh>
        </geometry>
      </collision>
      <visual name='wrist_2_link_visual'>
        <pose>0 0 -0.12 0 -0 0</pose>
        <geometry>
          <mesh>
            <scale>1 1 1</scale>
            <uri>model://ur16e/meshes/visual/wrist2.dae</uri>
          </mesh>
        </geometry>
      </visual>
    </link>
    <joint name='wrist_3_joint' type='revolute'>
      <pose relative_to='wrist_2_link'>0 0.11655 -0 -1.5708 0 -0</pose>
      <parent>wrist_2_link</parent>
      <child>wrist_3_link</child>
      <axis>
        <xyz>0 0 1</xyz>
        <limit>
          <lower>-6.28319</lower>
          <upper>6.28319</upper>
          <effort>54</effort>
          <velocity>3.14159</velocity>
        </limit>
        <dynamics>
          <damping>0</damping>
          <friction>0</friction>
          <spring_reference>0</spring_reference>
          <spring_stiffness>0</spring_stiffness>
        </dynamics>
      </axis>
    </joint>
    <link name='wrist_3_link'>
      <pose relative_to='wrist_3_joint'>0 0 0 0 -0 0</pose>
      <inertial>
        <pose>0 0 -0.044 0 -0 0</pose>
        <mass>0.907</mass>
        <inertia>
          <ixx>0.00117</ixx>
          <ixy>0</ixy>
          <ixz>0</ixz>
          <iyy>0.00118</iyy>
          <iyz>0</iyz>
          <izz>0.00084</izz>
        </inertia>
      </inertial>
      <collision name='wrist_3_link_collision'>
        <pose>0 0 -0.1168 1.5708 -0 0</pose>
        <geometry>
          <mesh>
            <scale>1 1 1</scale>
            <uri>model://ur16e/meshes/collision/wrist3.stl</uri>
          </mesh>
        </geometry>
      </collision>
      <visual name='wrist_3_link_visual'>
        <pose>0 0 -0.1168 1.5708 -0 0</pose>
        <geometry>
          <mesh>
            <scale>1 1 1</scale>
            <uri>model://ur16e/meshes/visual/wrist3.dae</uri>
          </mesh>
        </geometry>
      </visual>
    </link>

    <plugin name='controlboard_ur16e' filename='libgazebo_yarp_controlboard.so'>
      <yarpConfigurationFile>model://ur16e/conf/controlboard_ur16e.ini</yarpConfigurationFile>
    </plugin>

    <plugin name='robotinterface_ur16e_yarp' filename='libgazebo_yarp_robotinterface.so'>
      <yarpRobotInterfaceConfigurationFile>model://ur16e/conf/ur16e_nws_yarp.xml</yarpRobotInterfaceConfigurationFile>
    </plugin>
  </model>
</sdf>
